Workbook

Sheet Tour Cost
A1: Bushido: the Way of the Warrior : Cost and Margin
A2: Blue = input you can change. Fora comparable = Fora portal rate for sample dates (trip is undated; sample run Mar 8 to 20, 2027). Yellow = missing price, fill in column D (yen) or E (dollars). Days follow the Bushido trip page.
A4: Exchange rate (yen per dollar) | B4: 158.19 | C4: xe.com mid-market, Oct 13 2026
A5: Travelers | B5: ='Room Pricing'!B21 -> 12 | C5: From the party mix on the Room Pricing sheet
A6: Price per person, sharing a double ($) | B6: =ROUNDDOWN(B54+B8,-1) -> 2750 | C6: Formula: cost plus profit cap, rounded down to $10. Singles and groups of 4: Room Pricing sheet
A7: People per room (double occupancy) | B7: 2
A8: Profit cap per traveler ($) | B8: 500 | C8: Maximum profit per person
A9: Leader costs in price (1 = yes, 0 = no) | B9: 1 | C9: Your own room, rail, meals etc. split across travelers
A11: Category | B11: Item | C11: Dates | D11: Unit cost (¥) | E11: Unit cost ($) | F11: Qty | G11: Basis | H11: Cost per traveler ($) | I11: Status | J11: Source / note
A12: Lodging
A13: Lodging | B13: Tokyo: Ryogoku View Hotel (Sumida) | C13: Days 1 to 3 (3 nights) | E13: 105 | F13: 3 | G13: per room | H13: =IF(E13="","",IF(G13="per room",E13*F13/$B$7,IF(G13="per group",E13*F13/$B$5,E13*F13))) -> 157.5 | I13: Fora comparable | J13: Fora portal list total, Mon Mar 8 to Thu Mar 11, 2027, 2 adults 1 room: $315 for 3 nights. 1 adult $230; 4 adults 1 room $579. Standard tier; see Stay Tiers.
A14: Lodging | B14: Kyoto: Miyako City Kintetsu Kyoto Station | C14: Days 4 to 7 (4 nights) | E14: 81 | F14: 4 | G14: per room | H14: =IF(E14="","",IF(G14="per room",E14*F14/$B$7,IF(G14="per group",E14*F14/$B$5,E14*F14))) -> 162 | I14: Fora comparable | J14: Fora portal list total, Thu Mar 11 to Mon Mar 15, 2027: $324 for 4 nights, 1 or 2 adults. For 3 nights a 4-adult room was $835, more than 2 doubles, so a group of 4 takes 2 doubles. Day 7 calligraphy in Osaka is a day trip from Kyoto.
A15: Lodging | B15: Koyasan: Shukubo Ekoin (temple lodging) | C15: Day 8 (1 night) | E15: 254 | F15: 1 | G15: per room | H15: =IF(E15="","",IF(G15="per room",E15*F15/$B$7,IF(G15="per group",E15*F15/$B$5,E15*F15))) -> 127 | I15: Fora comparable | J15: Fora portal list total, Mon Jan 18 to Tue Jan 19, 2027 (no Koyasan temple shows rates for March): 1 or 2 adults $254; 4 adults 1 room $485. Ekoin stays include a vegetarian shojin ryori dinner and breakfast (walkintoluxury.com Ekoin listing; japan-guide: Koyasan shukubo rates include dinner and breakfast).
A16: Lodging | B16: Chikatsuyu: Minshuku Chikatsuyu, Main House, dinner, breakfast and lunch box | C16: Days 9 and 10 (2 nights) | D16: 32400 | E16: =IF(D16="","",D16/$B$4) -> 204.81699 | F16: 2 | G16: per room | H16: =IF(E16="","",IF(G16="per room",E16*F16/$B$7,IF(G16="per group",E16*F16/$B$5,E16*F16))) -> 204.81699 | I16: Quote | J16: kumano-tour-creation.com: ¥16,200 per person sharing, ¥18,400 single, onsen tax included. One minshuku may not hold 13; the Annex has only 2 rooms. Expect to split the group across village minshuku.
A17: Lodging | B17: Shingu: Hotel New Palace | C17: Day 11 (1 night) | E17: 104 | F17: 1 | G17: per room | H17: =IF(E17="","",IF(G17="per room",E17*F17/$B$7,IF(G17="per group",E17*F17/$B$5,E17*F17))) -> 52 | I17: Fora comparable | J17: Fora portal list total, Thu Mar 18 to Fri Mar 19, 2027: 1 or 2 adults $104; no 4-adult rate.
A18: Lodging | B18: Tokyo final night: Ryogoku View Hotel | C18: Day 12 (1 night) | E18: 105 | F18: 1 | G18: per room | H18: =IF(E18="","",IF(G18="per room",E18*F18/$B$7,IF(G18="per group",E18*F18/$B$5,E18*F18))) -> 52.5 | I18: Estimate | J18: The trip page says Day 12 ends with a final night in Tokyo. One night at the Days 1 to 3 Fora rate. Set Qty to 0 if the trip ends on arrival.
A19: Transport
A20: Transport | B20: Tokaido Shinkansen Tokyo to Kyoto (Nozomi, reserved) | C20: Day 4 | D20: 14170 | E20: =IF(D20="","",D20/$B$4) -> 89.575827 | F20: 1 | G20: per person | H20: =IF(E20="","",IF(G20="per room",E20*F20/$B$7,IF(G20="per group",E20*F20/$B$5,E20*F20))) -> 89.575827 | I20: Quote | J20: shinkansen.tabiris.com, normal season. JR group discount (8 or more) takes 10% or 15% off the base fare only; not applied here.
A21: Transport | B21: Kyoto Subway and Bus 1-Day Pass | C21: Days 4 to 6 | D21: 1100 | E21: =IF(D21="","",D21/$B$4) -> 6.9536633 | F21: 3 | G21: per person | H21: =IF(E21="","",IF(G21="per room",E21*F21/$B$7,IF(G21="per group",E21*F21/$B$5,E21*F21))) -> 20.86099 | I21: Quote | J21: Kyoto City press release, Mar 2026. Fushimi Inari, Ryoan-ji, Arashiyama, Gion.
A22: Transport | B22: JR Kyoto to Osaka and back for the calligraphy class (Shigino, Joto-ku) | C22: Day 7 | D22: 960 | E22: =IF(D22="","",D22/$B$4) -> 6.0686516 | F22: 2 | G22: per person | H22: =IF(E22="","",IF(G22="per room",E22*F22/$B$7,IF(G22="per group",E22*F22/$B$5,E22*F22))) -> 12.137303 | I22: Estimate | J22: Kyoto to Shigino fare not found. JR Kyoto to Shin-Imamiya, farther across Osaka, is ¥960 (Ekitan), used as the upper bound each way. Kyoto to Osaka alone is ¥580.
A23: Transport | B23: JR Kyoto to Shin-Imamiya, change to the Nankai Koya Line | C23: Day 8 | D23: 960 | E23: =IF(D23="","",D23/$B$4) -> 6.0686516 | F23: 1 | G23: per person | H23: =IF(E23="","",IF(G23="per room",E23*F23/$B$7,IF(G23="per group",E23*F23/$B$5,E23*F23))) -> 6.0686516 | I23: Quote | J23: Ekitan, Kyoto to Shin-Imamiya via Osaka, ¥960
A24: Transport | B24: Nankai Shin-Imamiya to Koyasan: limited express Koya, cable car, Koyasan bus | C24: Day 8 | D24: 2990 | E24: =IF(D24="","",D24/$B$4) -> 18.901321 | F24: 1 | G24: per person | H24: =IF(E24="","",IF(G24="per room",E24*F24/$B$7,IF(G24="per group",E24*F24/$B$5,E24*F24))) -> 18.901321 | I24: Estimate | J24: Fares quoted from Namba, one stop before Shin-Imamiya. Sum of published parts: base fare incl. cable car ¥1,430 (Nankai), limited express charge ¥1,100 (Nankai), bus to Senjuinbashi ¥460 (japan-guide)
A25: Transport | B25: Koyasan to Osaka: bus, cable car, Nankai (no limited express) | C25: Day 9 | D25: 1890 | E25: =IF(D25="","",D25/$B$4) -> 11.947658 | F25: 1 | G25: per person | H25: =IF(E25="","",IF(G25="per room",E25*F25/$B$7,IF(G25="per group",E25*F25/$B$5,E25*F25))) -> 11.947658 | I25: Estimate | J25: ¥1,430 Nankai fare plus ¥460 bus
A26: Transport | B26: JR Limited Express Kuroshio Tennoji to Kii-Tanabe (reserved) | C26: Day 9 | D26: 5370 | E26: =IF(D26="","",D26/$B$4) -> 33.94652 | F26: 1 | G26: per person | H26: =IF(E26="","",IF(G26="per room",E26*F26/$B$7,IF(G26="per group",E26*F26/$B$5,E26*F26))) -> 33.94652 | I26: Quote | J26: jr-group.jp, normal season, Oct 2026
A27: Transport | B27: Ryujin Bus Kumano Hongu Line 4-day pass | C27: Days 9 to 11 | D27: 5000 | E27: =IF(D27="","",D27/$B$4) -> 31.607561 | F27: 1 | G27: per person | H27: =IF(E27="","",IF(G27="per room",E27*F27/$B$7,IF(G27="per group",E27*F27/$B$5,E27*F27))) -> 31.607561 | I27: Quote | J27: ryujinbus.com: Kii-Tanabe, Takijiri, Hongu, Hosshinmon-oji (routes 80/81/84/85). Single fares to Takijiri and between Chikatsuyu and Hongu were not found. The page does not name Chikatsuyu as a stop, though the route runs through it; confirm.
A28: Transport | B28: Bus Hongu to Shingu (Kumano Kotsu) | C28: Day 11 | D28: 1560 | E28: =IF(D28="","",D28/$B$4) -> 9.8615589 | F28: 1 | G28: per person | H28: =IF(E28="","",IF(G28="per room",E28*F28/$B$7,IF(G28="per group",E28*F28/$B$5,E28*F28))) -> 9.8615589 | I28: Quote | J28: japan-guide.com. The river boat starts at Michi-no-eki Dorokyo Kaido Kumanogawa on this road; confirm the stop.
A29: Transport | B29: JR Shingu to Tokyo via Shin-Osaka (Kuroshio and Nozomi, through ticket) | C29: Day 12 | D29: 20090 | E29: =IF(D29="","",D29/$B$4) -> 126.99918 | F29: 1 | G29: per person | H29: =IF(E29="","",IF(G29="per room",E29*F29/$B$7,IF(G29="per group",E29*F29/$B$5,E29*F29))) -> 126.99918 | I29: Quote | J29: jr-group.jp, normal season. Via Nagoya (Nanki plus Nozomi) is about ¥18,830 as two tickets.
A30: Transport | B30: Luggage forwarding Kyoto hotel to Shingu hotel (Yamato, size 140) | C30: Day 8 | D30: 2190 | E30: =IF(D30="","",D30/$B$4) -> 13.844112 | F30: 1 | G30: per person | H30: =IF(E30="","",IF(G30="per room",E30*F30/$B$7,IF(G30="per group",E30*F30/$B$5,E30*F30))) -> 13.844112 | I30: Quote | J30: Yamato within Kansai, size 140, cash rate effective Apr 2024. Travelers carry a day pack through Koyasan and the Kumano Kodo.
A31: Transport | B31: Rail passes (not used) | D31: 0 | E31: =IF(D31="","",D31/$B$4) -> 0 | F31: 0 | G31: per person | H31: =IF(E31="","",IF(G31="per room",E31*F31/$B$7,IF(G31="per group",E31*F31/$B$5,E31*F31))) -> 0 | I31: Quote | J31: Point tickets total about ¥42,510 for the JR legs. 7-day Japan Rail Pass is ¥53,000 from Oct 2026; Ise-Kumano-Wakayama Area Pass ¥16,500 covers ¥14,460 of fares here.
A32: Training
A33: Training | B33: Feeling Samurai Soul with Yusuke (kimono, tea, meditation, sword handling) | C33: Day 2 | D33: 15000 | E33: =IF(D33="","",D33/$B$4) -> 94.822682 | F33: 1 | G33: per person | H33: =IF(E33="","",IF(G33="per room",E33*F33/$B$7,IF(G33="per group",E33*F33/$B$5,E33*F33))) -> 94.822682 | I33: Quote | J33: Airbnb Experiences listing 79594, from ¥15,000 per guest, 2.5 h. No group rate listed.
A34: Training | B34: KAMUI private Kengido and samurai experience | C34: Day 3 | D34: 598950 | E34: =IF(D34="","",D34/$B$4) -> 3786.2697 | F34: 1 | G34: per group | H34: =IF(E34="","",IF(G34="per room",E34*F34/$B$7,IF(G34="per group",E34*F34/$B$5,E34*F34))) -> 315.52247 | I34: Estimate | J34: 2026 Kanagawa DMO tariff (wholesale): ¥330,000 per group plus ¥16,500 per person plus 10%, worked for 13 people. Venue is in Kanagawa, 60 min, venue cost extra. A Tokyo workshop at Hotel Chinzanso is price on request.
A35: Training | B35: Yushinkan Kyoto: Samurai Training with the Modern-day Musashi | C35: Day 6 | D35: 20000 | E35: =IF(D35="","",D35/$B$4) -> 126.43024 | F35: 1 | G35: per person | H35: =IF(E35="","",IF(G35="per room",E35*F35/$B$7,IF(G35="per group",E35*F35/$B$5,E35*F35))) -> 126.43024 | I35: Quote | J35: yushinkankyoto.com, ¥20,000 tax incl., 90 min. Max 9 per session, so the group needs 2 sessions. The listed plan has the sensei perform tameshigiri as a demonstration; guests do not cut.
A36: Training | B36: Samurai Calligraphy with the oversized brush (Samurai Honor, Osaka) | C36: Day 7 | D36: 9900 | E36: =IF(D36="","",D36/$B$4) -> 62.58297 | F36: 1 | G36: per person | H36: =IF(E36="","",IF(G36="per room",E36*F36/$B$7,IF(G36="per group",E36*F36/$B$5,E36*F36))) -> 62.58297 | I36: Quote | J36: nta.co.jp, from ¥9,900 tax incl. Brush 5 times the usual size, 150 cm paper. Up to 20 per slot.
A37: Training | B37: Musuhi Budojo: kenjutsu and Ryukyu karate with Matsufune Asami | C37: Day 10 | E37: =IF(D37="","",D37/$B$4) | F37: 1 | G37: per person | H37: =IF(E37="","",IF(G37="per room",E37*F37/$B$7,IF(G37="per group",E37*F37/$B$5,E37*F37))) | I37: MISSING | J37: No published price found. Ask the dojo.
A38: Admissions
A39: Admissions | B39: Japanese Sword Museum | C39: Day 2 | D39: 1000 | E39: =IF(D39="","",D39/$B$4) -> 6.3215121 | F39: 1 | G39: per person | H39: =IF(E39="","",IF(G39="per room",E39*F39/$B$7,IF(G39="per group",E39*F39/$B$5,E39*F39))) -> 6.3215121 | I39: Quote | J39: touken.or.jp; fee varies by exhibition
A40: Admissions | B40: Ryoan-ji | C40: Day 5 | D40: 600 | E40: =IF(D40="","",D40/$B$4) -> 3.7929073 | F40: 1 | G40: per person | H40: =IF(E40="","",IF(G40="per room",E40*F40/$B$7,IF(G40="per group",E40*F40/$B$5,E40*F40))) -> 3.7929073 | I40: Quote | J40: japan-guide.com, Dec 2025
A41: Admissions | B41: Kinkaku-ji (optional) | C41: Day 5 | D41: 500 | E41: =IF(D41="","",D41/$B$4) -> 3.1607561 | F41: 0 | G41: per person | H41: =IF(E41="","",IF(G41="per room",E41*F41/$B$7,IF(G41="per group",E41*F41/$B$5,E41*F41))) -> 0 | I41: Quote | J41: japan-guide.com. The page lists Kinkaku-ji or Ryoan-ji; Qty 0. Set to 1 to include.
A42: Admissions | B42: Tea ceremony, Camellia (shared session) | C42: Day 5 | D42: 3000 | E42: =IF(D42="","",D42/$B$4) -> 18.964536 | F42: 1 | G42: per person | H42: =IF(E42="","",IF(G42="per room",E42*F42/$B$7,IF(G42="per group",E42*F42/$B$5,E42*F42))) -> 18.964536 | I42: Quote | J42: tea-kyoto.com, 45 min. Private session ¥8,000 per person.
...

Sheet Room Pricing
A1: Bushido: the Way of the Warrior : Price by Room Type
A2: Blue = input. Lodging is the whole stay per room. Every other cost comes from the Tour Cost sheet.
A4: Stay | B4: Nights | C4: Single room ($) | D4: Double room ($) | E4: Room(s) for 4 ($) | F4: Notes
A5: Tokyo, Ryogoku View Hotel | B5: 3 | C5: 230 | D5: ='Tour Cost'!E13*'Tour Cost'!F13 -> 315 | E5: 579 | F5: Fora: 1 adult $230; 2 adults $315; 4 adults in 1 room $579.
A6: Kyoto, Miyako City Kintetsu Kyoto Station | B6: 4 | C6: 324 | D6: ='Tour Cost'!E14*'Tour Cost'!F14 -> 324 | E6: =2*D6 -> 648 | F6: Fora, 4 nights: 1 or 2 adults $324. A 4-adult room costs more than 2 doubles.
A7: Koyasan, Shukubo Ekoin | B7: 1 | C7: 254 | D7: ='Tour Cost'!E15*'Tour Cost'!F15 -> 254 | E7: 485 | F7: Fora (January comparable): 1 or 2 adults $254; 4 adults $485.
A8: Chikatsuyu, Minshuku Chikatsuyu | B8: 2 | C8: =18400*2/'Tour Cost'!$B$4 -> 232.63165 | D8: ='Tour Cost'!E16*'Tour Cost'!F16 -> 409.63398 | E8: =2*D8 -> 819.26797 | F8: Per person ¥18,400 single, ¥16,200 sharing, per night. Group of 4 at the sharing rate.
A9: Shingu, Hotel New Palace | B9: 1 | C9: 104 | D9: ='Tour Cost'!E17*'Tour Cost'!F17 -> 104 | E9: =2*D9 -> 208 | F9: Fora: 1 or 2 adults $104; no 4-adult room.
A10: Tokyo final night, Ryogoku View Hotel | B10: 1 | C10: =C5/3 -> 76.666667 | D10: ='Tour Cost'!E18*'Tour Cost'!F18 -> 105 | E10: =E5/3 -> 193 | F10: One night at the Days 1 to 3 rates. Set Tour Cost Qty to 0 and this row to 0 to drop it.
A11: Lodging, whole trip | C11: =SUM(C5:C10) -> 1221.2983 | D11: =SUM(D5:D10) -> 1511.634 | E11: =SUM(E5:E10) -> 2932.268
A13: Room type | B13: People per room | C13: Lodging per person | D13: Other costs per person | E13: Your costs, per traveler | F13: Cost per person | G13: Price per person | H13: Profit per person
A14: Single | B14: 1 | C14: =C11 -> 1221.2983 | D14: =SUMIFS('Tour Cost'!H12:H49,'Tour Cost'!G12:G49,"per person")+SUMIFS('Tour Cost'!H12:H49,'Tour Cost'!G12:G49,"per group") -> 1316.1546 | E14: ='Tour Cost'!H51 -> 185.16087 | F14: =C14+D14+E14 -> 2722.6138 | G14: =ROUNDDOWN(F14+'Tour Cost'!B8,-1) -> 3220 | H14: =G14-F14 -> 497.38619
A15: Couple (shared double) | B15: 2 | C15: =D11/2 -> 755.81699 | D15: =SUMIFS('Tour Cost'!H12:H49,'Tour Cost'!G12:G49,"per person")+SUMIFS('Tour Cost'!H12:H49,'Tour Cost'!G12:G49,"per group") -> 1316.1546 | E15: ='Tour Cost'!H51 -> 185.16087 | F15: =C15+D15+E15 -> 2257.1325 | G15: =ROUNDDOWN(F15+'Tour Cost'!B8,-1) -> 2750 | H15: =G15-F15 -> 492.86751
A16: Group of 4 (shared rooms) | B16: 4 | C16: =E11/4 -> 733.06699 | D16: =SUMIFS('Tour Cost'!H12:H49,'Tour Cost'!G12:G49,"per person")+SUMIFS('Tour Cost'!H12:H49,'Tour Cost'!G12:G49,"per group") -> 1316.1546 | E16: ='Tour Cost'!H51 -> 185.16087 | F16: =C16+D16+E16 -> 2234.3825 | G16: =ROUNDDOWN(F16+'Tour Cost'!B8,-1) -> 2730 | H16: =G16-F16 -> 495.61751
A19: Party mix (sets the traveler count used for group costs)
A20: Singles | B20: 0
A21: Travelers (total) | B21: =B20+2*B22+4*B23 -> 12
A22: Couples | B22: 6
A23: Groups of 4 | B23: 0
A24: Group revenue | B24: =B20*G14+2*B22*G15+4*B23*G16 -> 33000
A25: Group cost | B25: =B20*F14+2*B22*F15+4*B23*F16 -> 27085.59
A26: Group profit | B26: =B24-B25 -> 5914.4101
A27: KAMUI is a fixed group price worked for 13 people; it and your own costs are split across the travelers above, so prices change when the mix changes. Yushinkan takes 9 per session, so 12 travelers need 2 sessions.
A29: Example mixes for a group of 12
A30: Mix | B30: Singles | C30: Couples | D30: Groups of 4 | E30: Group revenue | F30: Group cost | G30: Group profit
A31: All couples | B31: 0 | C31: 6 | D31: 0 | E31: =B31*$G$14+2*C31*$G$15+4*D31*$G$16 -> 33000 | F31: =B31*$F$14+2*C31*$F$15+4*D31*$F$16 -> 27085.59 | G31: =E31-F31 -> 5914.4101
A32: Two singles, five couples | B32: 2 | C32: 5 | D32: 0 | E32: =B32*$G$14+2*C32*$G$15+4*D32*$G$16 -> 33940 | F32: =B32*$F$14+2*C32*$F$15+4*D32*$F$16 -> 28016.553 | G32: =E32-F32 -> 5923.4475
A33: Four singles, four couples | B33: 4 | C33: 4 | D33: 0 | E33: =B33*$G$14+2*C33*$G$15+4*D33*$G$16 -> 34880 | F33: =B33*$F$14+2*C33*$F$15+4*D33*$F$16 -> 28947.515 | G33: =E33-F33 -> 5932.4849
A34: Couples and one group of 4 | B34: 0 | C34: 4 | D34: 1 | E34: =B34*$G$14+2*C34*$G$15+4*D34*$G$16 -> 32920 | F34: =B34*$F$14+2*C34*$F$15+4*D34*$F$16 -> 26994.59 | G34: =E34-F34 -> 5925.4101
A35: Two singles, three couples, one group of 4 | B35: 2 | C35: 3 | D35: 1 | E35: =B35*$G$14+2*C35*$G$15+4*D35*$G$16 -> 33860 | F35: =B35*$F$14+2*C35*$F$15+4*D35*$F$16 -> 27925.553 | G35: =E35-F35 -> 5934.4475
A36: Three groups of 4 | B36: 0 | C36: 0 | D36: 3 | E36: =B36*$G$14+2*C36*$G$15+4*D36*$G$16 -> 32760 | F36: =B36*$F$14+2*C36*$F$15+4*D36*$F$16 -> 26812.59 | G36: =E36-F36 -> 5947.4101
A38: Each row is 12 travelers, so KAMUI and your own costs split the same way in every row.

Sheet Stay Tiers
A1: Bushido: Stay Tiers
A2: Three levels of hotel in the same neighborhoods. Totals are per room for the whole stay, from the Fora portal on the sample dates (Koyasan: January comparable). A group of 4 takes 2 doubles where no 4-person room was offered. Chikatsuyu and Shingu have one option each, so all tiers use them.
A4: Stay | B4: Nights | C4: Tier | D4: Hotel | E4: Area | F4: Single room ($) | G4: Double room ($) | H4: Room(s) for 4 ($)
A5: Tokyo | B5: 3 | C5: Standard | D5: Ryogoku View Hotel | E5: Ryogoku, Sumida | F5: 230 | G5: 315 | H5: 579
A6: Tokyo | B6: 3 | C6: Superior | D6: The Gate Hotel Ryogoku by Hulic | E6: Ryogoku, Sumida | F6: 530 | G6: 530 | H6: 1060
A7: Tokyo | B7: 3 | C7: Premium | D7: Onyado Nono Asakusa Natural Hot Springs | E7: Asakusa, across the Sumida River | F7: 824 | G7: 1419 | H7: 2838
A8: Kyoto | B8: 4 | C8: Standard | D8: Miyako City Kintetsu Kyoto Station | E8: Kyoto Station | F8: 324 | G8: 324 | H8: 648
A9: Kyoto | B9: 4 | C9: Superior | D9: Mitsui Garden Hotel Kyoto Station | E9: Kyoto Station | F9: 564 | G9: 464 | H9: 928
A10: Kyoto | B10: 4 | C10: Premium | D10: Hotel Granvia Kyoto | E10: In Kyoto Station | F10: 937 | G10: 976 | H10: 1952
A11: Koyasan | B11: 1 | C11: Standard | D11: Shukubo Ekoin | E11: Koyasan | F11: 254 | G11: 254 | H11: 485
A12: Koyasan | B12: 1 | C12: Superior | D12: Shukubo Ekoin | E12: Koyasan | F12: 254 | G12: 254 | H12: 485
A13: Koyasan | B13: 1 | C13: Premium | D13: Koyasan Rengejoin | E13: Koyasan | F13: 969 | G13: 1008 | H13: 1897
A14: Chikatsuyu | B14: 2 | C14: All tiers | D14: ='Room Pricing'!A8 -> Chikatsuyu, Minshuku Chikatsuyu | E14: Chikatsuyu | F14: ='Room Pricing'!C8 -> 232.63165 | G14: ='Room Pricing'!D8 -> 409.63398 | H14: ='Room Pricing'!E8 -> 819.26797
A15: Shingu | B15: 1 | C15: All tiers | D15: ='Room Pricing'!A9 -> Shingu, Hotel New Palace | E15: Shingu | F15: ='Room Pricing'!C9 -> 104 | G15: ='Room Pricing'!D9 -> 104 | H15: ='Room Pricing'!E9 -> 208
A16: Tokyo final night: one night at the Tokyo tier rate (one third of the 3-night total).
A18: Price per person by tier
A19: Tier | B19: Room type | C19: People per room | D19: Lodging per person | E19: Other costs per person | F19: Your costs, per traveler | G19: Cost per person | H19: Price per person | I19: Profit per person
A20: Standard | B20: Single | C20: 1 | D20: =(F5*4/3+F8+F11+F14+F15)/1 -> 1221.2983 | E20: ='Room Pricing'!D15 -> 1316.1546 | F20: ='Room Pricing'!E15 -> 185.16087 | G20: =D20+E20+F20 -> 2722.6138 | H20: =ROUNDDOWN(G20+'Tour Cost'!$B$8,-1) -> 3220 | I20: =H20-G20 -> 497.38619
A21: Standard | B21: Couple (shared double) | C21: 2 | D21: =(G5*4/3+G8+G11+G14+G15)/2 -> 755.81699 | E21: ='Room Pricing'!D15 -> 1316.1546 | F21: ='Room Pricing'!E15 -> 185.16087 | G21: =D21+E21+F21 -> 2257.1325 | H21: =ROUNDDOWN(G21+'Tour Cost'!$B$8,-1) -> 2750 | I21: =H21-G21 -> 492.86751
A22: Standard | B22: Group of 4 (shared rooms) | C22: 4 | D22: =(H5*4/3+H8+H11+H14+H15)/4 -> 733.06699 | E22: ='Room Pricing'!D15 -> 1316.1546 | F22: ='Room Pricing'!E15 -> 185.16087 | G22: =D22+E22+F22 -> 2234.3825 | H22: =ROUNDDOWN(G22+'Tour Cost'!$B$8,-1) -> 2730 | I22: =H22-G22 -> 495.61751
A23: Superior | B23: Single | C23: 1 | D23: =(F6*4/3+F9+F12+F14+F15)/1 -> 1861.2983 | E23: ='Room Pricing'!D15 -> 1316.1546 | F23: ='Room Pricing'!E15 -> 185.16087 | G23: =D23+E23+F23 -> 3362.6138 | H23: =ROUNDDOWN(G23+'Tour Cost'!$B$8,-1) -> 3860 | I23: =H23-G23 -> 497.38619
A24: Superior | B24: Couple (shared double) | C24: 2 | D24: =(G6*4/3+G9+G12+G14+G15)/2 -> 969.15033 | E24: ='Room Pricing'!D15 -> 1316.1546 | F24: ='Room Pricing'!E15 -> 185.16087 | G24: =D24+E24+F24 -> 2470.4658 | H24: =ROUNDDOWN(G24+'Tour Cost'!$B$8,-1) -> 2970 | I24: =H24-G24 -> 499.53418
A25: Superior | B25: Group of 4 (shared rooms) | C25: 4 | D25: =(H6*4/3+H9+H12+H14+H15)/4 -> 963.40033 | E25: ='Room Pricing'!D15 -> 1316.1546 | F25: ='Room Pricing'!E15 -> 185.16087 | G25: =D25+E25+F25 -> 2464.7158 | H25: =ROUNDDOWN(G25+'Tour Cost'!$B$8,-1) -> 2960 | I25: =H25-G25 -> 495.28418
A26: Premium | B26: Single | C26: 1 | D26: =(F7*4/3+F10+F13+F14+F15)/1 -> 3341.2983 | E26: ='Room Pricing'!D15 -> 1316.1546 | F26: ='Room Pricing'!E15 -> 185.16087 | G26: =D26+E26+F26 -> 4842.6138 | H26: =ROUNDDOWN(G26+'Tour Cost'!$B$8,-1) -> 5340 | I26: =H26-G26 -> 497.38619
A27: Premium | B27: Couple (shared double) | C27: 2 | D27: =(G7*4/3+G10+G13+G14+G15)/2 -> 2194.817 | E27: ='Room Pricing'!D15 -> 1316.1546 | F27: ='Room Pricing'!E15 -> 185.16087 | G27: =D27+E27+F27 -> 3696.1325 | H27: =ROUNDDOWN(G27+'Tour Cost'!$B$8,-1) -> 4190 | I27: =H27-G27 -> 493.86751
A28: Premium | B28: Group of 4 (shared rooms) | C28: 4 | D28: =(H7*4/3+H10+H13+H14+H15)/4 -> 2165.067 | E28: ='Room Pricing'!D15 -> 1316.1546 | F28: ='Room Pricing'!E15 -> 185.16087 | G28: =D28+E28+F28 -> 3666.3825 | H28: =ROUNDDOWN(G28+'Tour Cost'!$B$8,-1) -> 4160 | I28: =H28-G28 -> 493.61751
A30: Other costs and your costs are the same in every tier (Room Pricing sheet). Your own room is counted at the Standard single rate.
