Workbook

Sheet Tour Cost
A1: Rassera! to Yōtei! 2027 : Cost and Margin, 12 Travelers
A2: Blue = input you can change. Fora comparable = Fora portal rate on the latest matching weekday it prices (March 2027). Yellow = missing price, fill in column D (yen) or E (dollars). Dates follow the Rassera! to Yōtei! itinerary, Aug 2 to 12, 2027.
A4: Exchange rate (yen per dollar) | B4: 158.19 | C4: xe.com mid-market, Oct 13 2026
A5: Travelers | B5: ='Room Pricing'!B21 -> 12 | C5: From the party mix on the Room Pricing sheet
A6: Price per person, sharing a double ($) | B6: =ROUNDDOWN(B52+B8,-1) -> 3220 | C6: Formula: cost plus profit cap, rounded down to $10. Singles and groups of 4: Room Pricing sheet
A7: People per room (double occupancy) | B7: 2
A8: Profit cap per traveler ($) | B8: 500 | C8: Maximum profit per person
A9: Leader costs in price (1 = yes, 0 = no) | B9: 1 | C9: Your own room, rail, meals etc. split across travelers
A11: Category | B11: Item | C11: Dates | D11: Unit cost (¥) | E11: Unit cost ($) | F11: Qty | G11: Basis | H11: Cost per traveler ($) | I11: Status | J11: Source / note
A12: Lodging
A13: Lodging | B13: Tokyo: Sequence Miyashita Park | C13: Aug 2 (1 night) | E13: 288.86 | F13: 1 | G13: per room | H13: =IF(E13="","",IF(G13="per room",E13*F13/$B$7,IF(G13="per group",E13*F13/$B$5,E13*F13))) -> 144.43 | I13: Estimate | J13: Booking.com public rate for Jul 29 to Aug 2, 2027 ($1,155.44 for 4 nights). Not found in Fora portal search.
A14: Lodging | B14: Morioka station-area hotel, Sansa week | C14: Aug 3 (1 night) | D14: 20262 | E14: =IF(D14="","",D14/$B$4) -> 128.08648 | F14: 1 | G14: per room | H14: =IF(E14="","",IF(G14="per room",E14*F14/$B$7,IF(G14="per group",E14*F14/$B$5,E14*F14))) -> 64.043239 | I14: Estimate | J14: Same Aug 2, 2026 survey: Aomori 3-hotel lowest average was 2.92 times the Morioka 13-hotel average, so Morioka is about ¥20,262. Off-season Fora rate at Metropolitan New Wing was $62.65.
A15: Lodging | B15: Aomori city hotel, Nebuta week | C15: Aug 4 to 8 (5 nights) | D15: 59166 | E15: =IF(D15="","",D15/$B$4) -> 374.01859 | F15: 5 | G15: per room | H15: =IF(E15="","",IF(G15="per room",E15*F15/$B$7,IF(G15="per group",E15*F15/$B$5,E15*F15))) -> 935.04646 | I15: Estimate | J15: August Nebuta-week rate: average lowest price at the 3 major Aomori hotels on sale for Aug 2, 2026 (Agoda survey, aomori-join.com, Mar 2026), outlier hotel excluded. The survey does not state room type or occupancy. Off-season Fora rate at Super Hotel Aomori was $47 a night.
A16: Lodging | B16: Lake Toya: Toya Onsen Hotel Hanabi, Mountain View Twin, room only | C16: Aug 9 to 11 (3 nights) | E16: 122.67 | F16: 3 | G16: per room | H16: =IF(E16="","",IF(G16="per room",E16*F16/$B$7,IF(G16="per group",E16*F16/$B$5,E16*F16))) -> 184.005 | I16: Fora comparable | J16: Fora portal, Mon Mar 15 to Thu Mar 18, 2027: $368.01 total for 3 nights incl. taxes and fees. August will price higher.
A17: Lodging | B17: Tokyo: Sequence Miyashita Park | C17: Aug 12 (1 night) | E17: 288.86 | F17: 0 | G17: per room | H17: =IF(E17="","",IF(G17="per room",E17*F17/$B$7,IF(G17="per group",E17*F17/$B$5,E17*F17))) -> 0 | I17: Estimate | J17: Optional closing night; Qty 0 because the trip ends with the Aug 12 flight. Set to 1 if you add it.
A18: Transport
A19: Transport | B19: Shinkansen Tokyo to Morioka (Hayabusa, reserved) | C19: Aug 3 | D19: 15450 | E19: =IF(D19="","",D19/$B$4) -> 97.667362 | F19: 1 | G19: per person | H19: =IF(E19="","",IF(G19="per room",E19*F19/$B$7,IF(G19="per group",E19*F19/$B$5,E19*F19))) -> 97.667362 | I19: Quote | J19: Published fare, ¥9,020 fare plus ¥6,430 reserved-seat charge
A20: Transport | B20: JR East-South Hokkaido Rail Pass (6 days) | C20: Aug 4 to 9 | D20: 40000 | E20: =IF(D20="","",D20/$B$4) -> 252.86048 | F20: 1 | G20: per person | H20: =IF(E20="","",IF(G20="per room",E20*F20/$B$7,IF(G20="per group",E20*F20/$B$5,E20*F20))) -> 252.86048 | I20: Quote | J20: JR East official price. Covers Morioka to Aomori, Hachinohe, Hirosaki and the Gono Line, Shin-Aomori to Kikonai, and the limited express to Toya.
A21: Transport | B21: Train Goshogawara to Aomori after the parade (21:21, change at Kawabe, arr. 22:55) | C21: Aug 8 | D21: 0 | E21: =IF(D21="","",D21/$B$4) -> 0 | F21: 1 | G21: per person | H21: =IF(E21="","",IF(G21="per room",E21*F21/$B$7,IF(G21="per group",E21*F21/$B$5,E21*F21))) -> 0 | I21: Quote | J21: Covered by the rail pass. Times from Ekitan last-train search on the Oct 2026 timetable; confirm the August 2027 timetable.
A22: Transport | B22: Bus Toya Station to Toyako Onsen and back | C22: Aug 9, Aug 12 | D22: 400 | E22: =IF(D22="","",D22/$B$4) -> 2.5286048 | F22: 2 | G22: per person | H22: =IF(E22="","",IF(G22="per room",E22*F22/$B$7,IF(G22="per group",E22*F22/$B$5,E22*F22))) -> 5.0572097 | I22: Quote | J22: Donan Bus, ¥400 each way
A23: Transport | B23: Chartered microbus with driver: Lake Hill Farm, Fukidashi Park, Noboribetsu, back to Toya | C23: Aug 11 | D23: 145000 | E23: =IF(D23="","",D23/$B$4) -> 916.61926 | F23: 1 | G23: per group | H23: =IF(E23="","",IF(G23="per room",E23*F23/$B$7,IF(G23="per group",E23*F23/$B$5,E23*F23))) -> 76.384938 | I23: Estimate | J23: Hire Car Japan published rate: microbus, 9 hours, outside Sapporo, ¥145,000 incl. driver, fuel and tolls. Rate is for Sapporo-based hire; a Toya start is not quoted. Seats 13 to 15 with luggage.
A24: Transport | B24: Train Toya to New Chitose Airport (local and Rapid Airport) | C24: Aug 12 | D24: 3100 | E24: =IF(D24="","",D24/$B$4) -> 19.596688 | F24: 1 | G24: per person | H24: =IF(E24="","",IF(G24="per room",E24*F24/$B$7,IF(G24="per group",E24*F24/$B$5,E24*F24))) -> 19.596688 | I24: Quote | J24: Ekitan fare ¥3,100, no limited express, about 2 h 39 min with 2 changes
A25: Transport | B25: Flight New Chitose to Haneda (JAL) | C25: Aug 12 | E25: 105 | F25: 1 | G25: per person | H25: =IF(E25="","",IF(G25="per room",E25*F25/$B$7,IF(G25="per group",E25*F25/$B$5,E25*F25))) -> 105 | I25: Quote | J25: Google Flights, Aug 12, 2027, lowest JAL nonstop fare incl. taxes, checked Oct 13, 2026
A26: Transport | B26: Luggage forwarding Tokyo to Lake Toya hotel (1 large bag) | C26: Aug 3 | D26: 3130 | E26: =IF(D26="","",D26/$B$4) -> 19.786333 | F26: 1 | G26: per person | H26: =IF(E26="","",IF(G26="per room",E26*F26/$B$7,IF(G26="per group",E26*F26/$B$5,E26*F26))) -> 19.786333 | I26: Estimate | J26: Yamato size 140, Kanto to Hokkaido, ¥2,930 to 3,130 (japanauthentic.com); high end used
A27: Transport | B27: Airport Limousine Bus Haneda to Shibuya | C27: Aug 2 | D27: 1300 | E27: =IF(D27="","",D27/$B$4) -> 8.2179657 | F27: 1 | G27: per person | H27: =IF(E27="","",IF(G27="per room",E27*F27/$B$7,IF(G27="per group",E27*F27/$B$5,E27*F27))) -> 8.2179657 | I27: Quote | J27: Adult fare. Narita arrivals cost more.
A28: Transport | B28: Bus Aomori Station to Sannai-Maruyama and back | C28: Aug 5 | D28: 310 | E28: =IF(D28="","",D28/$B$4) -> 1.9596688 | F28: 2 | G28: per person | H28: =IF(E28="","",IF(G28="per room",E28*F28/$B$7,IF(G28="per group",E28*F28/$B$5,E28*F28))) -> 3.9193375 | I28: Quote | J28: ¥310 each way. The JR Hachinohe Line to Kabushima and Tanesashi is covered by the rail pass.
A29: Festivals
A30: Festivals | B30: Nebuta Aug 7 daytime parade plus fireworks seat package | C30: Aug 7 | D30: 9500 | E30: =IF(D30="","",D30/$B$4) -> 60.054365 | F30: 1 | G30: per person | H30: =IF(E30="","",IF(G30="per room",E30*F30/$B$7,IF(G30="per group",E30*F30/$B$5,E30*F30))) -> 60.054365 | I30: Estimate | J30: 2026 package price ¥9,500; 2027 not published
A31: Festivals | B31: Haneto costume rental | C31: Aug 4 | D31: 4000 | E31: =IF(D31="","",D31/$B$4) -> 25.286048 | F31: 1 | G31: per person | H31: =IF(E31="","",IF(G31="per room",E31*F31/$B$7,IF(G31="per group",E31*F31/$B$5,E31*F31))) -> 25.286048 | I31: Estimate | J31: Full set about ¥4,000; tabi, zori and hanagasa can be extra
A32: Admissions
A33: Admissions | B33: Nebuta no Ie Wa Rasse | C33: Aug 5 | D33: 620 | E33: =IF(D33="","",D33/$B$4) -> 3.9193375 | F33: 1 | G33: per person | H33: =IF(E33="","",IF(G33="per room",E33*F33/$B$7,IF(G33="per group",E33*F33/$B$5,E33*F33))) -> 3.9193375 | I33: Quote | J33: Adult admission
A34: Admissions | B34: Aomori Museum of Art | C34: Aug 5 | D34: 700 | E34: =IF(D34="","",D34/$B$4) -> 4.4250585 | F34: 1 | G34: per person | H34: =IF(E34="","",IF(G34="per room",E34*F34/$B$7,IF(G34="per group",E34*F34/$B$5,E34*F34))) -> 4.4250585 | I34: Quote | J34: Collection exhibition, adult
A35: Admissions | B35: Sannai-Maruyama Jomon Site | C35: Aug 5 | D35: 410 | E35: =IF(D35="","",D35/$B$4) -> 2.59182 | F35: 1 | G35: per person | H35: =IF(E35="","",IF(G35="per room",E35*F35/$B$7,IF(G35="per group",E35*F35/$B$5,E35*F35))) -> 2.59182 | I35: Quote | J35: Adult admission
A36: Admissions | B36: Hirosaki Castle Honmaru | C36: Aug 8 | D36: 250 | E36: =IF(D36="","",D36/$B$4) -> 1.580378 | F36: 1 | G36: per person | H36: =IF(E36="","",IF(G36="per room",E36*F36/$B$7,IF(G36="per group",E36*F36/$B$5,E36*F36))) -> 1.580378 | I36: Quote | J36: Group rate for 10 or more (¥320 individual)
A37: Admissions | B37: Hirosaki MOCA | C37: Aug 8 | D37: 1600 | E37: =IF(D37="","",D37/$B$4) -> 10.114419 | F37: 1 | G37: per person | H37: =IF(E37="","",IF(G37="per room",E37*F37/$B$7,IF(G37="per group",E37*F37/$B$5,E37*F37))) -> 10.114419 | I37: Estimate | J37: Current Collection 2026-2027 price; the August 2027 exhibition is not announced
A38: Admissions | B38: Tachineputa Museum | C38: Aug 8 | D38: 650 | E38: =IF(D38="","",D38/$B$4) -> 4.1089829 | F38: 1 | G38: per person | H38: =IF(E38="","",IF(G38="per room",E38*F38/$B$7,IF(G38="per group",E38*F38/$B$5,E38*F38))) -> 4.1089829 | I38: Quote | J38: Exhibition room, adult
A39: Admissions | B39: Lake Toya cruise with Nakajima landing | C39: Aug 10 | D39: 1600 | E39: =IF(D39="","",D39/$B$4) -> 10.114419 | F39: 1 | G39: per person | H39: =IF(E39="","",IF(G39="per room",E39*F39/$B$7,IF(G39="per group",E39*F39/$B$5,E39*F39))) -> 10.114419 | I39: Quote | J39: Toyako Kisen adult fare; summer boats land on Nakajima
A40: Admissions | B40: Noboribetsu Jigokudani | C40: Aug 11 | D40: 0 | E40: =IF(D40="","",D40/$B$4) -> 0 | F40: 1 | G40: per person | H40: =IF(E40="","",IF(G40="per room",E40*F40/$B$7,IF(G40="per group",E40*F40/$B$5,E40*F40))) -> 0 | I40: Quote | J40: Free of charge (noboribetsu-spa.jp)
A41: Admissions | B41: Noboribetsu Date Jidai Mura (optional) | C41: Aug 11 | D41: 3000 | E41: =IF(D41="","",D41/$B$4) -> 18.964536 | F41: 0 | G41: per person | H41: =IF(E41="","",IF(G41="per room",E41*F41/$B$7,IF(G41="per group",E41*F41/$B$5,E41*F41))) -> 0 | I41: Quote | J41: Group rate for 8 or more (¥3,300 individual). Qty set to 0; change to 1 to include.
A42: Group meals
...

Sheet Room Pricing
A1: Rassera! to Yōtei! 2027 : Price by Room Type
A2: Blue = input. Lodging is the whole stay per room. Every other cost comes from the Tour Cost sheet.
A4: Stay | B4: Nights | C4: Single room ($) | D4: Double room ($) | E4: Room(s) for 4 ($) | F4: Notes
A5: Tokyo, Sequence Miyashita Park | B5: 1 | C5: 189 | D5: ='Tour Cost'!E13*'Tour Cost'!F13 -> 288.86 | E5: =2*D5 -> 577.72 | F5: Single: Booking.com, 1 adult, Jul 29, 2027 ($189). Double: Tour Cost row. Group of 4 takes 2 doubles.
A6: Morioka, station-area hotel | B6: 1 | C6: ='Tour Cost'!E14*'Tour Cost'!F14 -> 128.08648 | D6: ='Tour Cost'!E14*'Tour Cost'!F14 -> 128.08648 | E6: =2*D6 -> 256.17296 | F6: Survey rate per room; the survey does not state occupancy, so the same rate is used for 1 or 2 people. Group of 4 takes 2 rooms.
A7: Aomori, Nebuta week | B7: 5 | C7: ='Tour Cost'!E15*'Tour Cost'!F15 -> 1870.0929 | D7: ='Tour Cost'!E15*'Tour Cost'!F15 -> 1870.0929 | E7: =2*D7 -> 3740.1859 | F7: Survey rate per room; occupancy not stated, so the same rate is used for 1 or 2 people. Group of 4 takes 2 rooms.
A8: Lake Toya, Toya Onsen Hotel Hanabi | B8: 3 | C8: 155.43 | D8: ='Tour Cost'!E16*'Tour Cost'!F16 -> 368.01 | E8: 654.33 | F8: Fora portal, Mar 15 to 18, 2027: Single Room with breakfast $155.43; Mountain View Twin $368.01; Economy Quadruple, lakeside, 4 adults $654.33.
A9: Lodging, whole trip | C9: =SUM(C5:C8) -> 2342.6094 | D9: =SUM(D5:D8) -> 2655.0494 | E9: =SUM(E5:E8) -> 5228.4088
A13: Room type | B13: People per room | C13: Lodging per person | D13: Other costs per person | E13: Your costs, per traveler | F13: Cost per person | G13: Price per person | H13: Profit per person
A14: Single | B14: 1 | C14: =C9 -> 2342.6094 | D14: =SUMIFS('Tour Cost'!H12:H47,'Tour Cost'!G12:G47,"per person")+SUMIFS('Tour Cost'!H12:H47,'Tour Cost'!G12:G47,"per group") -> 1119.8134 | E14: ='Tour Cost'!H49 -> 282.16982 | F14: =C14+D14+E14 -> 3744.5926 | G14: =ROUNDDOWN(F14+'Tour Cost'!B8,-1) -> 4240 | H14: =G14-F14 -> 495.40736
A15: Couple (shared double) | B15: 2 | C15: =D9/2 -> 1327.5247 | D15: =SUMIFS('Tour Cost'!H12:H47,'Tour Cost'!G12:G47,"per person")+SUMIFS('Tour Cost'!H12:H47,'Tour Cost'!G12:G47,"per group") -> 1119.8134 | E15: ='Tour Cost'!H49 -> 282.16982 | F15: =C15+D15+E15 -> 2729.5079 | G15: =ROUNDDOWN(F15+'Tour Cost'!B8,-1) -> 3220 | H15: =G15-F15 -> 490.49206
A16: Group of 4 (shared rooms) | B16: 4 | C16: =E9/4 -> 1307.1022 | D16: =SUMIFS('Tour Cost'!H12:H47,'Tour Cost'!G12:G47,"per person")+SUMIFS('Tour Cost'!H12:H47,'Tour Cost'!G12:G47,"per group") -> 1119.8134 | E16: ='Tour Cost'!H49 -> 282.16982 | F16: =C16+D16+E16 -> 2709.0854 | G16: =ROUNDDOWN(F16+'Tour Cost'!B8,-1) -> 3200 | H16: =G16-F16 -> 490.91456
A19: Party mix (sets the traveler count used for group costs)
A20: Singles | B20: 0
A21: Travelers (total) | B21: =B20+2*B22+4*B23 -> 12
A22: Couples | B22: 6
A23: Groups of 4 | B23: 0
A24: Group revenue | B24: =B20*G14+2*B22*G15+4*B23*G16 -> 38640
A25: Group cost | B25: =B20*F14+2*B22*F15+4*B23*F16 -> 32754.095
A26: Group profit | B26: =B24-B25 -> 5885.9048
A27: The microbus seats 13 to 15 with luggage, including you. The microbus and your own costs are split across the travelers above, so prices change when the mix changes.
A29: Example mixes for a group of 12
A30: Mix | B30: Singles | C30: Couples | D30: Groups of 4 | E30: Group revenue | F30: Group cost | G30: Group profit
A31: All couples | B31: 0 | C31: 6 | D31: 0 | E31: =B31*$G$14+2*C31*$G$15+4*D31*$G$16 -> 38640 | F31: =B31*$F$14+2*C31*$F$15+4*D31*$F$16 -> 32754.095 | G31: =E31-F31 -> 5885.9048
A32: Two singles, five couples | B32: 2 | C32: 5 | D32: 0 | E32: =B32*$G$14+2*C32*$G$15+4*D32*$G$16 -> 40680 | F32: =B32*$F$14+2*C32*$F$15+4*D32*$F$16 -> 34784.265 | G32: =E32-F32 -> 5895.7354
A33: Four singles, four couples | B33: 4 | C33: 4 | D33: 0 | E33: =B33*$G$14+2*C33*$G$15+4*D33*$G$16 -> 42720 | F33: =B33*$F$14+2*C33*$F$15+4*D33*$F$16 -> 36814.434 | G33: =E33-F33 -> 5905.566
A34: Couples and one group of 4 | B34: 0 | C34: 4 | D34: 1 | E34: =B34*$G$14+2*C34*$G$15+4*D34*$G$16 -> 38560 | F34: =B34*$F$14+2*C34*$F$15+4*D34*$F$16 -> 32672.405 | G34: =E34-F34 -> 5887.5948
A35: Two singles, three couples, one group of 4 | B35: 2 | C35: 3 | D35: 1 | E35: =B35*$G$14+2*C35*$G$15+4*D35*$G$16 -> 40600 | F35: =B35*$F$14+2*C35*$F$15+4*D35*$F$16 -> 34702.575 | G35: =E35-F35 -> 5897.4254
A36: Three groups of 4 | B36: 0 | C36: 0 | D36: 3 | E36: =B36*$G$14+2*C36*$G$15+4*D36*$G$16 -> 38400 | F36: =B36*$F$14+2*C36*$F$15+4*D36*$F$16 -> 32509.025 | G36: =E36-F36 -> 5890.9748
A38: Each row is 12 travelers, so the microbus and your own costs split the same way in every row.
